<!DOCTYPE html>
<html>
<head>
    <title>Unit Test Report</title>
    <meta http-equiv="Content-Type" content="text/html; charset=UTF-8"/>

<style>
body {
    font-family: Calibri, "Trebuchet MS", sans-serif;
}
* {
    word-break: break-all;
}
table, td, th, .dataid {
    border: 1px solid #aaa;
    border-collapse: collapse;
    background: #fff;
}
section {
    background: rgba(0, 0, 0, 0.05);
    margin: 2ex;
    padding: 1ex;
    border: 1px solid #999;
    border-radius: 5px;
}
h1 {
    font-size: 130%;
}
h2 {
    font-size: 120%;
}
h3 {
    font-size: 100%;
}
h4 {
    font-size: 85%;
}
h1, h2, h3, h4, a[href] {
    cursor: pointer;
    color: #0074d9;
    text-decoration: none;
}
h3 strong, a.failed {
    color: #ff4136;
}
.failed {
    color: #ff4136;
}
a.success {
    color: #3d9970;
}
pre {
    font-family: 'Consolas', 'Deja Vu Sans Mono',
                 'Bitstream Vera Sans Mono', 'Monaco',
                 'Courier New', monospace;
}

.test-details,
.traceback {
    display: none;
}
section:target .test-details {
    display: block;
}

</style>
</head>
<body>
    <h1>Overview</h1>
    <section>
        <table>
            <tr>
                <th>Class</th>
                <th>Fail</th>
                <th class="failed">Error</th>
                <th>Skip</th>
                <th>Success</th>
                <th>Total</th>
            </tr>
                <tr>
                    <td>ubertool.ubertool.beerex.tests.test_beerex_unittest.TestBeerex</td>
                    <td>0</td>
                    <td class="failed">6</td>
                    <td>0</td>
                    <td>52</td>
                    <td>58</td>
                </tr>
                <tr>
                    <td>nose.failure.Failure</td>
                    <td>0</td>
                    <td class="failed">1</td>
                    <td>0</td>
                    <td>0</td>
                    <td>1</td>
                </tr>
            <tr>
                <td><strong>Total</strong></td>
                <td>0</td>
                <td class="failed">7</td>
                <td>0</td>
                <td>52</td>
                <td>59</td>
            </tr>
        </table>
    </section>
    <h1>Failure details</h1>
            <section>
                <h2>ubertool.ubertool.beerex.tests.test_beerex_unittest.TestBeerex (0 failures, 6 errors)</h2>
                <div>
                        <section id="ubertool.ubertool.beerex.tests.test_beerex_unittest.TestBeerex:test_beerex_ad_total_dose">
                            <h3>test_beerex_ad_total_dose: <strong>builtins.IndexError</strong></h3>
                            <div class="test-details">
                                <h4>Traceback</h4>
                                <pre class="traceback">Traceback (most recent call last):
  File "/anaconda/lib/python3.6/site-packages/pandas/core/series.py", line 778, in _set_with_engine
    self.index._engine.set_value(values, key, value)
  File "pandas/_libs/index.pyx", line 116, in pandas._libs.index.IndexEngine.set_value (pandas/_libs/index.c:4690)
  File "pandas/_libs/index.pyx", line 124, in pandas._libs.index.IndexEngine.set_value (pandas/_libs/index.c:4516)
  File "pandas/_libs/index.pyx", line 154, in pandas._libs.index.IndexEngine.get_loc (pandas/_libs/index.c:5126)
  File "pandas/_libs/hashtable_class_helper.pxi", line 1210, in pandas._libs.hashtable.PyObjectHashTable.get_item (pandas/_libs/hashtable.c:20523)
  File "pandas/_libs/hashtable_class_helper.pxi", line 1218, in pandas._libs.hashtable.PyObjectHashTable.get_item (pandas/_libs/hashtable.c:20477)
KeyError: 0

During handling of the above exception, another exception occurred:

Traceback (most recent call last):
  File "/anaconda/lib/python3.6/site-packages/pandas/core/indexes/base.py", line 2442, in get_loc
    return self._engine.get_loc(key)
  File "pandas/_libs/index.pyx", line 132, in pandas._libs.index.IndexEngine.get_loc (pandas/_libs/index.c:5280)
  File "pandas/_libs/index.pyx", line 154, in pandas._libs.index.IndexEngine.get_loc (pandas/_libs/index.c:5126)
  File "pandas/_libs/hashtable_class_helper.pxi", line 1210, in pandas._libs.hashtable.PyObjectHashTable.get_item (pandas/_libs/hashtable.c:20523)
  File "pandas/_libs/hashtable_class_helper.pxi", line 1218, in pandas._libs.hashtable.PyObjectHashTable.get_item (pandas/_libs/hashtable.c:20477)
KeyError: 0

During handling of the above exception, another exception occurred:

Traceback (most recent call last):
  File "/anaconda/lib/python3.6/site-packages/pandas/core/series.py", line 719, in setitem
    self._set_with_engine(key, value)
  File "/anaconda/lib/python3.6/site-packages/pandas/core/series.py", line 781, in _set_with_engine
    values[self.index.get_loc(key)] = value
  File "/anaconda/lib/python3.6/site-packages/pandas/core/indexes/base.py", line 2444, in get_loc
    return self._engine.get_loc(self._maybe_cast_indexer(key))
  File "pandas/_libs/index.pyx", line 132, in pandas._libs.index.IndexEngine.get_loc (pandas/_libs/index.c:5280)
  File "pandas/_libs/index.pyx", line 154, in pandas._libs.index.IndexEngine.get_loc (pandas/_libs/index.c:5126)
  File "pandas/_libs/hashtable_class_helper.pxi", line 1210, in pandas._libs.hashtable.PyObjectHashTable.get_item (pandas/_libs/hashtable.c:20523)
  File "pandas/_libs/hashtable_class_helper.pxi", line 1218, in pandas._libs.hashtable.PyObjectHashTable.get_item (pandas/_libs/hashtable.c:20477)
KeyError: 0

During handling of the above exception, another exception occurred:

Traceback (most recent call last):
  File "/anaconda/lib/python3.6/unittest/case.py", line 59, in testPartExecutor
    yield
  File "/anaconda/lib/python3.6/unittest/case.py", line 601, in run
    testMethod()
  File "/Users/puruckertom/git/qed/ubertool_ecorest/ubertool/ubertool/beerex/tests/test_beerex_unittest.py", line 656, in test_beerex_ad_total_dose
    beerex_empty.eec_spray(i)
  File "/Users/puruckertom/git/qed/ubertool_ecorest/ubertool/ubertool/beerex/beerex_exe.py", line 240, in eec_spray
    self.out_eec_soil[i] = np.nan
  File "/anaconda/lib/python3.6/site-packages/pandas/core/series.py", line 771, in __setitem__
    setitem(key, value)
  File "/anaconda/lib/python3.6/site-packages/pandas/core/series.py", line 728, in setitem
    values[key] = value
IndexError: index 0 is out of bounds for axis 0 with size 0
</pre>
                                <h4>Details</h4>
                                <pre>index 0 is out of bounds for axis 0 with size 0</pre>
                            </div>
                        </section>
                        <section id="ubertool.ubertool.beerex.tests.test_beerex_unittest.TestBeerex:test_beerex_aq_total_dose">
                            <h3>test_beerex_aq_total_dose: <strong>builtins.UnboundLocalError</strong></h3>
                            <div class="test-details">
                                <h4>Traceback</h4>
                                <pre class="traceback">Traceback (most recent call last):
  File "/anaconda/lib/python3.6/site-packages/pandas/core/series.py", line 778, in _set_with_engine
    self.index._engine.set_value(values, key, value)
  File "pandas/_libs/index.pyx", line 116, in pandas._libs.index.IndexEngine.set_value (pandas/_libs/index.c:4690)
  File "pandas/_libs/index.pyx", line 124, in pandas._libs.index.IndexEngine.set_value (pandas/_libs/index.c:4516)
  File "pandas/_libs/index.pyx", line 154, in pandas._libs.index.IndexEngine.get_loc (pandas/_libs/index.c:5126)
  File "pandas/_libs/hashtable_class_helper.pxi", line 1210, in pandas._libs.hashtable.PyObjectHashTable.get_item (pandas/_libs/hashtable.c:20523)
  File "pandas/_libs/hashtable_class_helper.pxi", line 1218, in pandas._libs.hashtable.PyObjectHashTable.get_item (pandas/_libs/hashtable.c:20477)
KeyError: 0

During handling of the above exception, another exception occurred:

Traceback (most recent call last):
  File "/anaconda/lib/python3.6/site-packages/pandas/core/indexes/base.py", line 2442, in get_loc
    return self._engine.get_loc(key)
  File "pandas/_libs/index.pyx", line 132, in pandas._libs.index.IndexEngine.get_loc (pandas/_libs/index.c:5280)
  File "pandas/_libs/index.pyx", line 154, in pandas._libs.index.IndexEngine.get_loc (pandas/_libs/index.c:5126)
  File "pandas/_libs/hashtable_class_helper.pxi", line 1210, in pandas._libs.hashtable.PyObjectHashTable.get_item (pandas/_libs/hashtable.c:20523)
  File "pandas/_libs/hashtable_class_helper.pxi", line 1218, in pandas._libs.hashtable.PyObjectHashTable.get_item (pandas/_libs/hashtable.c:20477)
KeyError: 0

During handling of the above exception, another exception occurred:

Traceback (most recent call last):
  File "/anaconda/lib/python3.6/site-packages/pandas/core/series.py", line 719, in setitem
    self._set_with_engine(key, value)
  File "/anaconda/lib/python3.6/site-packages/pandas/core/series.py", line 781, in _set_with_engine
    values[self.index.get_loc(key)] = value
  File "/anaconda/lib/python3.6/site-packages/pandas/core/indexes/base.py", line 2444, in get_loc
    return self._engine.get_loc(self._maybe_cast_indexer(key))
  File "pandas/_libs/index.pyx", line 132, in pandas._libs.index.IndexEngine.get_loc (pandas/_libs/index.c:5280)
  File "pandas/_libs/index.pyx", line 154, in pandas._libs.index.IndexEngine.get_loc (pandas/_libs/index.c:5126)
  File "pandas/_libs/hashtable_class_helper.pxi", line 1210, in pandas._libs.hashtable.PyObjectHashTable.get_item (pandas/_libs/hashtable.c:20523)
  File "pandas/_libs/hashtable_class_helper.pxi", line 1218, in pandas._libs.hashtable.PyObjectHashTable.get_item (pandas/_libs/hashtable.c:20477)
KeyError: 0

During handling of the above exception, another exception occurred:

Traceback (most recent call last):
  File "/Users/puruckertom/git/qed/ubertool_ecorest/ubertool/ubertool/beerex/tests/test_beerex_unittest.py", line 687, in test_beerex_aq_total_dose
    beerex_empty.eec_soil(i)
  File "/Users/puruckertom/git/qed/ubertool_ecorest/ubertool/ubertool/beerex/beerex_exe.py", line 253, in eec_soil
    self.out_eec_seed[i] = np.nan
  File "/anaconda/lib/python3.6/site-packages/pandas/core/series.py", line 771, in __setitem__
    setitem(key, value)
  File "/anaconda/lib/python3.6/site-packages/pandas/core/series.py", line 728, in setitem
    values[key] = value
IndexError: index 0 is out of bounds for axis 0 with size 0

During handling of the above exception, another exception occurred:

Traceback (most recent call last):
  File "/anaconda/lib/python3.6/unittest/case.py", line 59, in testPartExecutor
    yield
  File "/anaconda/lib/python3.6/unittest/case.py", line 601, in run
    testMethod()
  File "/Users/puruckertom/git/qed/ubertool_ecorest/ubertool/ubertool/beerex/tests/test_beerex_unittest.py", line 693, in test_beerex_aq_total_dose
    tab = [result, expected_results]
UnboundLocalError: local variable 'result' referenced before assignment
</pre>
                                <h4>Details</h4>
                                <pre>local variable 'result' referenced before assignment</pre>
                            </div>
                        </section>
                        <section id="ubertool.ubertool.beerex.tests.test_beerex_unittest.TestBeerex:test_beerex_aw_brood_total_dose">
                            <h3>test_beerex_aw_brood_total_dose: <strong>builtins.UnboundLocalError</strong></h3>
                            <div class="test-details">
                                <h4>Traceback</h4>
                                <pre class="traceback">Traceback (most recent call last):
  File "/anaconda/lib/python3.6/site-packages/pandas/core/series.py", line 778, in _set_with_engine
    self.index._engine.set_value(values, key, value)
  File "pandas/_libs/index.pyx", line 116, in pandas._libs.index.IndexEngine.set_value (pandas/_libs/index.c:4690)
  File "pandas/_libs/index.pyx", line 124, in pandas._libs.index.IndexEngine.set_value (pandas/_libs/index.c:4516)
  File "pandas/_libs/index.pyx", line 154, in pandas._libs.index.IndexEngine.get_loc (pandas/_libs/index.c:5126)
  File "pandas/_libs/hashtable_class_helper.pxi", line 1210, in pandas._libs.hashtable.PyObjectHashTable.get_item (pandas/_libs/hashtable.c:20523)
  File "pandas/_libs/hashtable_class_helper.pxi", line 1218, in pandas._libs.hashtable.PyObjectHashTable.get_item (pandas/_libs/hashtable.c:20477)
KeyError: 0

During handling of the above exception, another exception occurred:

Traceback (most recent call last):
  File "/anaconda/lib/python3.6/site-packages/pandas/core/indexes/base.py", line 2442, in get_loc
    return self._engine.get_loc(key)
  File "pandas/_libs/index.pyx", line 132, in pandas._libs.index.IndexEngine.get_loc (pandas/_libs/index.c:5280)
  File "pandas/_libs/index.pyx", line 154, in pandas._libs.index.IndexEngine.get_loc (pandas/_libs/index.c:5126)
  File "pandas/_libs/hashtable_class_helper.pxi", line 1210, in pandas._libs.hashtable.PyObjectHashTable.get_item (pandas/_libs/hashtable.c:20523)
  File "pandas/_libs/hashtable_class_helper.pxi", line 1218, in pandas._libs.hashtable.PyObjectHashTable.get_item (pandas/_libs/hashtable.c:20477)
KeyError: 0

During handling of the above exception, another exception occurred:

Traceback (most recent call last):
  File "/anaconda/lib/python3.6/site-packages/pandas/core/series.py", line 719, in setitem
    self._set_with_engine(key, value)
  File "/anaconda/lib/python3.6/site-packages/pandas/core/series.py", line 781, in _set_with_engine
    values[self.index.get_loc(key)] = value
  File "/anaconda/lib/python3.6/site-packages/pandas/core/indexes/base.py", line 2444, in get_loc
    return self._engine.get_loc(self._maybe_cast_indexer(key))
  File "pandas/_libs/index.pyx", line 132, in pandas._libs.index.IndexEngine.get_loc (pandas/_libs/index.c:5280)
  File "pandas/_libs/index.pyx", line 154, in pandas._libs.index.IndexEngine.get_loc (pandas/_libs/index.c:5126)
  File "pandas/_libs/hashtable_class_helper.pxi", line 1210, in pandas._libs.hashtable.PyObjectHashTable.get_item (pandas/_libs/hashtable.c:20523)
  File "pandas/_libs/hashtable_class_helper.pxi", line 1218, in pandas._libs.hashtable.PyObjectHashTable.get_item (pandas/_libs/hashtable.c:20477)
KeyError: 0

During handling of the above exception, another exception occurred:

Traceback (most recent call last):
  File "/Users/puruckertom/git/qed/ubertool_ecorest/ubertool/ubertool/beerex/tests/test_beerex_unittest.py", line 510, in test_beerex_aw_brood_total_dose
    beerex_empty.eec_spray(i)
  File "/Users/puruckertom/git/qed/ubertool_ecorest/ubertool/ubertool/beerex/beerex_exe.py", line 241, in eec_spray
    self.out_eec_seed[i] = np.nan
  File "/anaconda/lib/python3.6/site-packages/pandas/core/series.py", line 771, in __setitem__
    setitem(key, value)
  File "/anaconda/lib/python3.6/site-packages/pandas/core/series.py", line 728, in setitem
    values[key] = value
IndexError: index 0 is out of bounds for axis 0 with size 0

During handling of the above exception, another exception occurred:

Traceback (most recent call last):
  File "/anaconda/lib/python3.6/unittest/case.py", line 59, in testPartExecutor
    yield
  File "/anaconda/lib/python3.6/unittest/case.py", line 601, in run
    testMethod()
  File "/Users/puruckertom/git/qed/ubertool_ecorest/ubertool/ubertool/beerex/tests/test_beerex_unittest.py", line 516, in test_beerex_aw_brood_total_dose
    tab = [result, expected_results]
UnboundLocalError: local variable 'result' referenced before assignment
</pre>
                                <h4>Details</h4>
                                <pre>local variable 'result' referenced before assignment</pre>
                            </div>
                        </section>
                        <section id="ubertool.ubertool.beerex.tests.test_beerex_unittest.TestBeerex:test_beerex_aw_cell_total_dose">
                            <h3>test_beerex_aw_cell_total_dose: <strong>builtins.UnboundLocalError</strong></h3>
                            <div class="test-details">
                                <h4>Traceback</h4>
                                <pre class="traceback">Traceback (most recent call last):
  File "/anaconda/lib/python3.6/site-packages/pandas/core/series.py", line 778, in _set_with_engine
    self.index._engine.set_value(values, key, value)
  File "pandas/_libs/index.pyx", line 116, in pandas._libs.index.IndexEngine.set_value (pandas/_libs/index.c:4690)
  File "pandas/_libs/index.pyx", line 124, in pandas._libs.index.IndexEngine.set_value (pandas/_libs/index.c:4516)
  File "pandas/_libs/index.pyx", line 154, in pandas._libs.index.IndexEngine.get_loc (pandas/_libs/index.c:5126)
  File "pandas/_libs/hashtable_class_helper.pxi", line 1210, in pandas._libs.hashtable.PyObjectHashTable.get_item (pandas/_libs/hashtable.c:20523)
  File "pandas/_libs/hashtable_class_helper.pxi", line 1218, in pandas._libs.hashtable.PyObjectHashTable.get_item (pandas/_libs/hashtable.c:20477)
KeyError: 0

During handling of the above exception, another exception occurred:

Traceback (most recent call last):
  File "/anaconda/lib/python3.6/site-packages/pandas/core/indexes/base.py", line 2442, in get_loc
    return self._engine.get_loc(key)
  File "pandas/_libs/index.pyx", line 132, in pandas._libs.index.IndexEngine.get_loc (pandas/_libs/index.c:5280)
  File "pandas/_libs/index.pyx", line 154, in pandas._libs.index.IndexEngine.get_loc (pandas/_libs/index.c:5126)
  File "pandas/_libs/hashtable_class_helper.pxi", line 1210, in pandas._libs.hashtable.PyObjectHashTable.get_item (pandas/_libs/hashtable.c:20523)
  File "pandas/_libs/hashtable_class_helper.pxi", line 1218, in pandas._libs.hashtable.PyObjectHashTable.get_item (pandas/_libs/hashtable.c:20477)
KeyError: 0

During handling of the above exception, another exception occurred:

Traceback (most recent call last):
  File "/anaconda/lib/python3.6/site-packages/pandas/core/series.py", line 719, in setitem
    self._set_with_engine(key, value)
  File "/anaconda/lib/python3.6/site-packages/pandas/core/series.py", line 781, in _set_with_engine
    values[self.index.get_loc(key)] = value
  File "/anaconda/lib/python3.6/site-packages/pandas/core/indexes/base.py", line 2444, in get_loc
    return self._engine.get_loc(self._maybe_cast_indexer(key))
  File "pandas/_libs/index.pyx", line 132, in pandas._libs.index.IndexEngine.get_loc (pandas/_libs/index.c:5280)
  File "pandas/_libs/index.pyx", line 154, in pandas._libs.index.IndexEngine.get_loc (pandas/_libs/index.c:5126)
  File "pandas/_libs/hashtable_class_helper.pxi", line 1210, in pandas._libs.hashtable.PyObjectHashTable.get_item (pandas/_libs/hashtable.c:20523)
  File "pandas/_libs/hashtable_class_helper.pxi", line 1218, in pandas._libs.hashtable.PyObjectHashTable.get_item (pandas/_libs/hashtable.c:20477)
KeyError: 0

During handling of the above exception, another exception occurred:

Traceback (most recent call last):
  File "/Users/puruckertom/git/qed/ubertool_ecorest/ubertool/ubertool/beerex/tests/test_beerex_unittest.py", line 483, in test_beerex_aw_cell_total_dose
    beerex_empty.eec_seed(i)
  File "/Users/puruckertom/git/qed/ubertool_ecorest/ubertool/ubertool/beerex/beerex_exe.py", line 264, in eec_seed
    self.out_eec_tree[i] = np.nan
  File "/anaconda/lib/python3.6/site-packages/pandas/core/series.py", line 771, in __setitem__
    setitem(key, value)
  File "/anaconda/lib/python3.6/site-packages/pandas/core/series.py", line 728, in setitem
    values[key] = value
IndexError: index 0 is out of bounds for axis 0 with size 0

During handling of the above exception, another exception occurred:

Traceback (most recent call last):
  File "/anaconda/lib/python3.6/unittest/case.py", line 59, in testPartExecutor
    yield
  File "/anaconda/lib/python3.6/unittest/case.py", line 601, in run
    testMethod()
  File "/Users/puruckertom/git/qed/ubertool_ecorest/ubertool/ubertool/beerex/tests/test_beerex_unittest.py", line 489, in test_beerex_aw_cell_total_dose
    tab = [result, expected_results]
UnboundLocalError: local variable 'result' referenced before assignment
</pre>
                                <h4>Details</h4>
                                <pre>local variable 'result' referenced before assignment</pre>
                            </div>
                        </section>
                        <section id="ubertool.ubertool.beerex.tests.test_beerex_unittest.TestBeerex:test_beerex_aw_comb_total_dose">
                            <h3>test_beerex_aw_comb_total_dose: <strong>builtins.UnboundLocalError</strong></h3>
                            <div class="test-details">
                                <h4>Traceback</h4>
                                <pre class="traceback">Traceback (most recent call last):
  File "/anaconda/lib/python3.6/site-packages/pandas/core/series.py", line 778, in _set_with_engine
    self.index._engine.set_value(values, key, value)
  File "pandas/_libs/index.pyx", line 116, in pandas._libs.index.IndexEngine.set_value (pandas/_libs/index.c:4690)
  File "pandas/_libs/index.pyx", line 124, in pandas._libs.index.IndexEngine.set_value (pandas/_libs/index.c:4516)
  File "pandas/_libs/index.pyx", line 154, in pandas._libs.index.IndexEngine.get_loc (pandas/_libs/index.c:5126)
  File "pandas/_libs/hashtable_class_helper.pxi", line 1210, in pandas._libs.hashtable.PyObjectHashTable.get_item (pandas/_libs/hashtable.c:20523)
  File "pandas/_libs/hashtable_class_helper.pxi", line 1218, in pandas._libs.hashtable.PyObjectHashTable.get_item (pandas/_libs/hashtable.c:20477)
KeyError: 0

During handling of the above exception, another exception occurred:

Traceback (most recent call last):
  File "/anaconda/lib/python3.6/site-packages/pandas/core/indexes/base.py", line 2442, in get_loc
    return self._engine.get_loc(key)
  File "pandas/_libs/index.pyx", line 132, in pandas._libs.index.IndexEngine.get_loc (pandas/_libs/index.c:5280)
  File "pandas/_libs/index.pyx", line 154, in pandas._libs.index.IndexEngine.get_loc (pandas/_libs/index.c:5126)
  File "pandas/_libs/hashtable_class_helper.pxi", line 1210, in pandas._libs.hashtable.PyObjectHashTable.get_item (pandas/_libs/hashtable.c:20523)
  File "pandas/_libs/hashtable_class_helper.pxi", line 1218, in pandas._libs.hashtable.PyObjectHashTable.get_item (pandas/_libs/hashtable.c:20477)
KeyError: 0

During handling of the above exception, another exception occurred:

Traceback (most recent call last):
  File "/anaconda/lib/python3.6/site-packages/pandas/core/series.py", line 719, in setitem
    self._set_with_engine(key, value)
  File "/anaconda/lib/python3.6/site-packages/pandas/core/series.py", line 781, in _set_with_engine
    values[self.index.get_loc(key)] = value
  File "/anaconda/lib/python3.6/site-packages/pandas/core/indexes/base.py", line 2444, in get_loc
    return self._engine.get_loc(self._maybe_cast_indexer(key))
  File "pandas/_libs/index.pyx", line 132, in pandas._libs.index.IndexEngine.get_loc (pandas/_libs/index.c:5280)
  File "pandas/_libs/index.pyx", line 154, in pandas._libs.index.IndexEngine.get_loc (pandas/_libs/index.c:5126)
  File "pandas/_libs/hashtable_class_helper.pxi", line 1210, in pandas._libs.hashtable.PyObjectHashTable.get_item (pandas/_libs/hashtable.c:20523)
  File "pandas/_libs/hashtable_class_helper.pxi", line 1218, in pandas._libs.hashtable.PyObjectHashTable.get_item (pandas/_libs/hashtable.c:20477)
KeyError: 0

During handling of the above exception, another exception occurred:

Traceback (most recent call last):
  File "/Users/puruckertom/git/qed/ubertool_ecorest/ubertool/ubertool/beerex/tests/test_beerex_unittest.py", line 542, in test_beerex_aw_comb_total_dose
    beerex_empty.eec_soil(i)
  File "/Users/puruckertom/git/qed/ubertool_ecorest/ubertool/ubertool/beerex/beerex_exe.py", line 254, in eec_soil
    self.out_eec_tree[i] = np.nan
  File "/anaconda/lib/python3.6/site-packages/pandas/core/series.py", line 771, in __setitem__
    setitem(key, value)
  File "/anaconda/lib/python3.6/site-packages/pandas/core/series.py", line 728, in setitem
    values[key] = value
IndexError: index 0 is out of bounds for axis 0 with size 0

During handling of the above exception, another exception occurred:

Traceback (most recent call last):
  File "/anaconda/lib/python3.6/unittest/case.py", line 59, in testPartExecutor
    yield
  File "/anaconda/lib/python3.6/unittest/case.py", line 601, in run
    testMethod()
  File "/Users/puruckertom/git/qed/ubertool_ecorest/ubertool/ubertool/beerex/tests/test_beerex_unittest.py", line 548, in test_beerex_aw_comb_total_dose
    tab = [result, expected_results]
UnboundLocalError: local variable 'result' referenced before assignment
</pre>
                                <h4>Details</h4>
                                <pre>local variable 'result' referenced before assignment</pre>
                            </div>
                        </section>
                        <section id="ubertool.ubertool.beerex.tests.test_beerex_unittest.TestBeerex:test_beerex_aw_nectar_total_dose">
                            <h3>test_beerex_aw_nectar_total_dose: <strong>builtins.UnboundLocalError</strong></h3>
                            <div class="test-details">
                                <h4>Traceback</h4>
                                <pre class="traceback">Traceback (most recent call last):
  File "/anaconda/lib/python3.6/site-packages/pandas/core/series.py", line 778, in _set_with_engine
    self.index._engine.set_value(values, key, value)
  File "pandas/_libs/index.pyx", line 116, in pandas._libs.index.IndexEngine.set_value (pandas/_libs/index.c:4690)
  File "pandas/_libs/index.pyx", line 124, in pandas._libs.index.IndexEngine.set_value (pandas/_libs/index.c:4516)
  File "pandas/_libs/index.pyx", line 154, in pandas._libs.index.IndexEngine.get_loc (pandas/_libs/index.c:5126)
  File "pandas/_libs/hashtable_class_helper.pxi", line 1210, in pandas._libs.hashtable.PyObjectHashTable.get_item (pandas/_libs/hashtable.c:20523)
  File "pandas/_libs/hashtable_class_helper.pxi", line 1218, in pandas._libs.hashtable.PyObjectHashTable.get_item (pandas/_libs/hashtable.c:20477)
KeyError: 0

During handling of the above exception, another exception occurred:

Traceback (most recent call last):
  File "/anaconda/lib/python3.6/site-packages/pandas/core/indexes/base.py", line 2442, in get_loc
    return self._engine.get_loc(key)
  File "pandas/_libs/index.pyx", line 132, in pandas._libs.index.IndexEngine.get_loc (pandas/_libs/index.c:5280)
  File "pandas/_libs/index.pyx", line 154, in pandas._libs.index.IndexEngine.get_loc (pandas/_libs/index.c:5126)
  File "pandas/_libs/hashtable_class_helper.pxi", line 1210, in pandas._libs.hashtable.PyObjectHashTable.get_item (pandas/_libs/hashtable.c:20523)
  File "pandas/_libs/hashtable_class_helper.pxi", line 1218, in pandas._libs.hashtable.PyObjectHashTable.get_item (pandas/_libs/hashtable.c:20477)
KeyError: 0

During handling of the above exception, another exception occurred:

Traceback (most recent call last):
  File "/anaconda/lib/python3.6/site-packages/pandas/core/series.py", line 719, in setitem
    self._set_with_engine(key, value)
  File "/anaconda/lib/python3.6/site-packages/pandas/core/series.py", line 781, in _set_with_engine
    values[self.index.get_loc(key)] = value
  File "/anaconda/lib/python3.6/site-packages/pandas/core/indexes/base.py", line 2444, in get_loc
    return self._engine.get_loc(self._maybe_cast_indexer(key))
  File "pandas/_libs/index.pyx", line 132, in pandas._libs.index.IndexEngine.get_loc (pandas/_libs/index.c:5280)
  File "pandas/_libs/index.pyx", line 154, in pandas._libs.index.IndexEngine.get_loc (pandas/_libs/index.c:5126)
  File "pandas/_libs/hashtable_class_helper.pxi", line 1210, in pandas._libs.hashtable.PyObjectHashTable.get_item (pandas/_libs/hashtable.c:20523)
  File "pandas/_libs/hashtable_class_helper.pxi", line 1218, in pandas._libs.hashtable.PyObjectHashTable.get_item (pandas/_libs/hashtable.c:20477)
KeyError: 0

During handling of the above exception, another exception occurred:

Traceback (most recent call last):
  File "/Users/puruckertom/git/qed/ubertool_ecorest/ubertool/ubertool/beerex/tests/test_beerex_unittest.py", line 595, in test_beerex_aw_nectar_total_dose
    beerex_empty.eec_seed(i)
  File "/Users/puruckertom/git/qed/ubertool_ecorest/ubertool/ubertool/beerex/beerex_exe.py", line 264, in eec_seed
    self.out_eec_tree[i] = np.nan
  File "/anaconda/lib/python3.6/site-packages/pandas/core/series.py", line 771, in __setitem__
    setitem(key, value)
  File "/anaconda/lib/python3.6/site-packages/pandas/core/series.py", line 728, in setitem
    values[key] = value
IndexError: index 0 is out of bounds for axis 0 with size 0

During handling of the above exception, another exception occurred:

Traceback (most recent call last):
  File "/anaconda/lib/python3.6/unittest/case.py", line 59, in testPartExecutor
    yield
  File "/anaconda/lib/python3.6/unittest/case.py", line 601, in run
    testMethod()
  File "/Users/puruckertom/git/qed/ubertool_ecorest/ubertool/ubertool/beerex/tests/test_beerex_unittest.py", line 601, in test_beerex_aw_nectar_total_dose
    tab = [result, expected_results]
UnboundLocalError: local variable 'result' referenced before assignment
</pre>
                                <h4>Details</h4>
                                <pre>local variable 'result' referenced before assignment</pre>
                            </div>
                        </section>
                </div>
            </section>
            <section>
                <h2>nose.failure.Failure (0 failures, 1 errors)</h2>
                <div>
                        <section id="nose.failure.Failure:runTest">
                            <h3>runTest: <strong>builtins.ModuleNotFoundError</strong></h3>
                            <div class="test-details">
                                <h4>Traceback</h4>
                                <pre class="traceback">Traceback (most recent call last):
  File "/anaconda/lib/python3.6/unittest/case.py", line 59, in testPartExecutor
    yield
  File "/anaconda/lib/python3.6/unittest/case.py", line 601, in run
    testMethod()
  File "/anaconda/lib/python3.6/site-packages/nose/failure.py", line 39, in runTest
    raise self.exc_val.with_traceback(self.tb)
  File "/anaconda/lib/python3.6/site-packages/nose/loader.py", line 417, in loadTestsFromName
    addr.filename, addr.module)
  File "/anaconda/lib/python3.6/site-packages/nose/importer.py", line 47, in importFromPath
    return self.importFromDir(dir_path, fqname)
  File "/anaconda/lib/python3.6/site-packages/nose/importer.py", line 94, in importFromDir
    mod = load_module(part_fqname, fh, filename, desc)
  File "/anaconda/lib/python3.6/imp.py", line 234, in load_module
    return load_source(name, filename, file)
  File "/anaconda/lib/python3.6/imp.py", line 172, in load_source
    module = _load(spec)
  File "<frozen importlib._bootstrap>", line 675, in _load
  File "<frozen importlib._bootstrap>", line 655, in _load_unlocked
  File "<frozen importlib._bootstrap_external>", line 678, in exec_module
  File "<frozen importlib._bootstrap>", line 205, in _call_with_frames_removed
  File "/Users/puruckertom/git/qed/ubertool_ecorest/ubertool/ubertool/beerex/tests/test_beerex_integration.py", line 8, in <module>
    from StringIO import StringIO
ModuleNotFoundError: No module named 'StringIO'
</pre>
                                <h4>Details</h4>
                                <pre>No module named 'StringIO'</pre>
                            </div>
                        </section>
                </div>
            </section>

    <h1>All tests</h1>
    <section>
        <h2>ubertool.ubertool.beerex.tests.test_beerex_unittest.TestBeerex (0 failures, 6 errors)</h2>
        <ul>
                <li><a class="success">test_beerex_ad_acute_rq</a></li>
                <li><a class="success">test_beerex_ad_chronic_rq</a></li>
                <li><a class="failed" href="#ubertool.ubertool.beerex.tests.test_beerex_unittest.TestBeerex:test_beerex_ad_total_dose">test_beerex_ad_total_dose</a></li>
                <li><a class="success">test_beerex_aq_acute_rq</a></li>
                <li><a class="success">test_beerex_aq_chronic_rq</a></li>
                <li><a class="failed" href="#ubertool.ubertool.beerex.tests.test_beerex_unittest.TestBeerex:test_beerex_aq_total_dose">test_beerex_aq_total_dose</a></li>
                <li><a class="success">test_beerex_aw_brood_acute_rq</a></li>
                <li><a class="success">test_beerex_aw_brood_chronic_rq</a></li>
                <li><a class="failed" href="#ubertool.ubertool.beerex.tests.test_beerex_unittest.TestBeerex:test_beerex_aw_brood_total_dose">test_beerex_aw_brood_total_dose</a></li>
                <li><a class="success">test_beerex_aw_cell_acute_rq</a></li>
                <li><a class="success">test_beerex_aw_cell_chronic_rq</a></li>
                <li><a class="failed" href="#ubertool.ubertool.beerex.tests.test_beerex_unittest.TestBeerex:test_beerex_aw_cell_total_dose">test_beerex_aw_cell_total_dose</a></li>
                <li><a class="success">test_beerex_aw_comb_acute_rq</a></li>
                <li><a class="success">test_beerex_aw_comb_chronic_rq</a></li>
                <li><a class="failed" href="#ubertool.ubertool.beerex.tests.test_beerex_unittest.TestBeerex:test_beerex_aw_comb_total_dose">test_beerex_aw_comb_total_dose</a></li>
                <li><a class="success">test_beerex_aw_nectar_acute_rq</a></li>
                <li><a class="success">test_beerex_aw_nectar_chronic_rq</a></li>
                <li><a class="failed" href="#ubertool.ubertool.beerex.tests.test_beerex_unittest.TestBeerex:test_beerex_aw_nectar_total_dose">test_beerex_aw_nectar_total_dose</a></li>
                <li><a class="success">test_beerex_aw_pollen_acute_rq</a></li>
                <li><a class="success">test_beerex_aw_pollen_chronic_rq</a></li>
                <li><a class="success">test_beerex_aw_pollen_total_dose</a></li>
                <li><a class="success">test_beerex_aw_winter_acute_rq</a></li>
                <li><a class="success">test_beerex_aw_winter_chronic_rq</a></li>
                <li><a class="success">test_beerex_aw_winter_total_dose</a></li>
                <li><a class="success">test_beerex_eec_seed</a></li>
                <li><a class="success">test_beerex_eec_soil</a></li>
                <li><a class="success">test_beerex_eec_tree</a></li>
                <li><a class="success">test_beerex_ld6_acute_rq</a></li>
                <li><a class="success">test_beerex_ld6_chronic_rq</a></li>
                <li><a class="success">test_beerex_ld6_total_dose</a></li>
                <li><a class="success">test_beerex_lq1_acute_rq</a></li>
                <li><a class="success">test_beerex_lq1_chronic_rq</a></li>
                <li><a class="success">test_beerex_lq1_total_dose</a></li>
                <li><a class="success">test_beerex_lq2_acute_rq</a></li>
                <li><a class="success">test_beerex_lq2_chronic_rq</a></li>
                <li><a class="success">test_beerex_lq2_total_dose</a></li>
                <li><a class="success">test_beerex_lq3_acute_rq</a></li>
                <li><a class="success">test_beerex_lq3_chronic_rq</a></li>
                <li><a class="success">test_beerex_lq3_total_dose</a></li>
                <li><a class="success">test_beerex_lq4_acute_rq</a></li>
                <li><a class="success">test_beerex_lq4_chronic_rq</a></li>
                <li><a class="success">test_beerex_lq4_total_dose</a></li>
                <li><a class="success">test_beerex_lw1_acute_rq</a></li>
                <li><a class="success">test_beerex_lw1_chronic_rq</a></li>
                <li><a class="success">test_beerex_lw1_total_dose</a></li>
                <li><a class="success">test_beerex_lw2_acute_rq</a></li>
                <li><a class="success">test_beerex_lw2_chronic_rq</a></li>
                <li><a class="success">test_beerex_lw2_total_dose</a></li>
                <li><a class="success">test_beerex_lw3_acute_rq</a></li>
                <li><a class="success">test_beerex_lw3_chronic_rq</a></li>
                <li><a class="success">test_beerex_lw3_total_dose</a></li>
                <li><a class="success">test_beerex_lw4_acute_rq</a></li>
                <li><a class="success">test_beerex_lw4_chronic_rq</a></li>
                <li><a class="success">test_beerex_lw4_total_dose</a></li>
                <li><a class="success">test_beerex_lw5_acute_rq</a></li>
                <li><a class="success">test_beerex_lw5_chronic_rq</a></li>
                <li><a class="success">test_beerex_lw5_total_dose</a></li>
                <li><a class="success">test_eec_spray</a></li>
        </ul>
    </section>
    <section>
        <h2>nose.failure.Failure (0 failures, 1 errors)</h2>
        <ul>
                <li><a class="failed" href="#nose.failure.Failure:runTest">runTest</a></li>
        </ul>
    </section>
</body>
<script>
    Array.prototype.forEach.call(document.querySelectorAll('h1, h2, h3, h4'), function(el) {
        el.addEventListener('click', function() {
            el.nextElementSibling.style.display = document.defaultView.getComputedStyle(el.nextElementSibling).display == 'none' ? 'block' : 'none';
        })
    })
</script>
</html>